Traceback (most recent call last):
  File "/opt/hostedtoolcache/Python/3.8.18/x64/lib/python3.8/site-packages/jupyter_cache/executors/utils.py", line 58, in single_nb_execution
    executenb(
  File "/opt/hostedtoolcache/Python/3.8.18/x64/lib/python3.8/site-packages/nbclient/client.py", line 1305, in execute
    return NotebookClient(nb=nb, resources=resources, km=km, **kwargs).execute()
  File "/opt/hostedtoolcache/Python/3.8.18/x64/lib/python3.8/site-packages/jupyter_core/utils/__init__.py", line 165, in wrapped
    return loop.run_until_complete(inner)
  File "/opt/hostedtoolcache/Python/3.8.18/x64/lib/python3.8/asyncio/base_events.py", line 616, in run_until_complete
    return future.result()
  File "/opt/hostedtoolcache/Python/3.8.18/x64/lib/python3.8/site-packages/nbclient/client.py", line 705, in async_execute
    await self.async_execute_cell(
  File "/opt/hostedtoolcache/Python/3.8.18/x64/lib/python3.8/site-packages/nbclient/client.py", line 1058, in async_execute_cell
    await self._check_raise_for_error(cell, cell_index, exec_reply)
  File "/opt/hostedtoolcache/Python/3.8.18/x64/lib/python3.8/site-packages/nbclient/client.py", line 914, in _check_raise_for_error
    raise CellExecutionError.from_cell_and_msg(cell, exec_reply_content)
nbclient.exceptions.CellExecutionError: An error occurred while executing the following cell:
------------------
!pip install -q condacolab
import condacolab
condacolab.install()
------------------


[0;31m---------------------------------------------------------------------------[0m
[0;31mModuleNotFoundError[0m                       Traceback (most recent call last)
File [0;32m/opt/hostedtoolcache/Python/3.8.18/x64/lib/python3.8/site-packages/condacolab.py:26[0m
[1;32m     25[0m [38;5;28;01mtry[39;00m:
[0;32m---> 26[0m     [38;5;28;01mimport[39;00m[38;5;250m [39m[38;5;21;01mgoogle[39;00m[38;5;21;01m.[39;00m[38;5;21;01mcolab[39;00m
[1;32m     27[0m [38;5;28;01mexcept[39;00m [38;5;167;01mImportError[39;00m:

[0;31mModuleNotFoundError[0m: No module named 'google'

During handling of the above exception, another exception occurred:

[0;31mRuntimeError[0m                              Traceback (most recent call last)
Cell [0;32mIn[1], line 2[0m
[1;32m      1[0m get_ipython()[38;5;241m.[39msystem([38;5;124m'[39m[38;5;124mpip install -q condacolab[39m[38;5;124m'[39m)
[0;32m----> 2[0m [38;5;28;01mimport[39;00m[38;5;250m [39m[38;5;21;01mcondacolab[39;00m
[1;32m      3[0m condacolab[38;5;241m.[39minstall()

File [0;32m/opt/hostedtoolcache/Python/3.8.18/x64/lib/python3.8/site-packages/condacolab.py:28[0m
[1;32m     26[0m     [38;5;28;01mimport[39;00m[38;5;250m [39m[38;5;21;01mgoogle[39;00m[38;5;21;01m.[39;00m[38;5;21;01mcolab[39;00m
[1;32m     27[0m [38;5;28;01mexcept[39;00m [38;5;167;01mImportError[39;00m:
[0;32m---> 28[0m     [38;5;28;01mraise[39;00m [38;5;167;01mRuntimeError[39;00m([38;5;124m"[39m[38;5;124mThis module must ONLY run as part of a Colab notebook![39m[38;5;124m"[39m)
[1;32m     31[0m __version__ [38;5;241m=[39m [38;5;124m"[39m[38;5;124m0.1.6[39m[38;5;124m"[39m
[1;32m     32[0m __author__ [38;5;241m=[39m [38;5;124m"[39m[38;5;124mJaime Rodr√≠guez-Guerra <jaimergp@users.noreply.github.com>[39m[38;5;124m"[39m

[0;31mRuntimeError[0m: This module must ONLY run as part of a Colab notebook!

