Traceback (most recent call last):
  File "/opt/hostedtoolcache/Python/3.7.10/x64/lib/python3.7/site-packages/jupyter_cache/executors/utils.py", line 56, in single_nb_execution
    record_timing=False,
  File "/opt/hostedtoolcache/Python/3.7.10/x64/lib/python3.7/site-packages/nbclient/client.py", line 1112, in execute
    return NotebookClient(nb=nb, resources=resources, km=km, **kwargs).execute()
  File "/opt/hostedtoolcache/Python/3.7.10/x64/lib/python3.7/site-packages/nbclient/util.py", line 74, in wrapped
    return just_run(coro(*args, **kwargs))
  File "/opt/hostedtoolcache/Python/3.7.10/x64/lib/python3.7/site-packages/nbclient/util.py", line 53, in just_run
    return loop.run_until_complete(coro)
  File "/opt/hostedtoolcache/Python/3.7.10/x64/lib/python3.7/asyncio/base_events.py", line 587, in run_until_complete
    return future.result()
  File "/opt/hostedtoolcache/Python/3.7.10/x64/lib/python3.7/site-packages/nbclient/client.py", line 554, in async_execute
    cell, index, execution_count=self.code_cells_executed + 1
  File "/opt/hostedtoolcache/Python/3.7.10/x64/lib/python3.7/site-packages/nbclient/client.py", line 857, in async_execute_cell
    self._check_raise_for_error(cell, exec_reply)
  File "/opt/hostedtoolcache/Python/3.7.10/x64/lib/python3.7/site-packages/nbclient/client.py", line 760, in _check_raise_for_error
    raise CellExecutionError.from_cell_and_msg(cell, exec_reply_content)
nbclient.exceptions.CellExecutionError: An error occurred while executing the following cell:
------------------
#hv.extension('bokeh')

## Option-1: Define ranges of variables and pass to DynamicMap
#hv.DynamicMap(wave, kdims=['phase', 'freq']).redim.range(phase=(0.0,2*np.pi), freq=(0.1, 5))
hv.DynamicMap(wave, kdims=['phase', 'freq']).redim.values(phase=np.linspace(0.0,2*np.pi,20), freq=np.linsp(0.1, 5))

## Option-2: make dictionary of data points and pass to HoloMap
#data = {(phase, freq): wave(phase, freq) for (phase, freq) in zip(np.linspace(0.0,2*np.pi,20), np.linspace(0.1, 5, 20)) }
#hv.HoloMap(data, kdims=['phase', 'freq'])
------------------

[0;31m---------------------------------------------------------------------------[0m
[0;31mAttributeError[0m                            Traceback (most recent call last)
[0;32m<ipython-input-26-3e1a3c3e907a>[0m in [0;36m<module>[0;34m[0m
[1;32m      3[0m [0;31m## Option-1: Define ranges of variables and pass to DynamicMap[0m[0;34m[0m[0;34m[0m[0;34m[0m[0m
[1;32m      4[0m [0;31m#hv.DynamicMap(wave, kdims=['phase', 'freq']).redim.range(phase=(0.0,2*np.pi), freq=(0.1, 5))[0m[0;34m[0m[0;34m[0m[0;34m[0m[0m
[0;32m----> 5[0;31m [0mhv[0m[0;34m.[0m[0mDynamicMap[0m[0;34m([0m[0mwave[0m[0;34m,[0m [0mkdims[0m[0;34m=[0m[0;34m[[0m[0;34m'phase'[0m[0;34m,[0m [0;34m'freq'[0m[0;34m][0m[0;34m)[0m[0;34m.[0m[0mredim[0m[0;34m.[0m[0mvalues[0m[0;34m([0m[0mphase[0m[0;34m=[0m[0mnp[0m[0;34m.[0m[0mlinspace[0m[0;34m([0m[0;36m0.0[0m[0;34m,[0m[0;36m2[0m[0;34m*[0m[0mnp[0m[0;34m.[0m[0mpi[0m[0;34m,[0m[0;36m20[0m[0;34m)[0m[0;34m,[0m [0mfreq[0m[0;34m=[0m[0mnp[0m[0;34m.[0m[0mlinsp[0m[0;34m([0m[0;36m0.1[0m[0;34m,[0m [0;36m5[0m[0;34m)[0m[0;34m)[0m[0;34m[0m[0;34m[0m[0m
[0m[1;32m      6[0m [0;34m[0m[0m
[1;32m      7[0m [0;31m## Option-2: make dictionary of data points and pass to HoloMap[0m[0;34m[0m[0;34m[0m[0;34m[0m[0m

[0;32m/opt/hostedtoolcache/Python/3.7.10/x64/lib/python3.7/site-packages/numpy/__init__.py[0m in [0;36m__getattr__[0;34m(attr)[0m
[1;32m    302[0m [0;34m[0m[0m
[1;32m    303[0m             raise AttributeError("module {!r} has no attribute "
[0;32m--> 304[0;31m                                  "{!r}".format(__name__, attr))
[0m[1;32m    305[0m [0;34m[0m[0m
[1;32m    306[0m         [0;32mdef[0m [0m__dir__[0m[0;34m([0m[0;34m)[0m[0;34m:[0m[0;34m[0m[0;34m[0m[0m

[0;31mAttributeError[0m: module 'numpy' has no attribute 'linsp'
AttributeError: module 'numpy' has no attribute 'linsp'

