Traceback (most recent call last):
  File "/opt/hostedtoolcache/Python/3.8.18/x64/lib/python3.8/site-packages/jupyter_cache/executors/utils.py", line 58, in single_nb_execution
    executenb(
  File "/opt/hostedtoolcache/Python/3.8.18/x64/lib/python3.8/site-packages/nbclient/client.py", line 1305, in execute
    return NotebookClient(nb=nb, resources=resources, km=km, **kwargs).execute()
  File "/opt/hostedtoolcache/Python/3.8.18/x64/lib/python3.8/site-packages/jupyter_core/utils/__init__.py", line 165, in wrapped
    return loop.run_until_complete(inner)
  File "/opt/hostedtoolcache/Python/3.8.18/x64/lib/python3.8/asyncio/base_events.py", line 616, in run_until_complete
    return future.result()
  File "/opt/hostedtoolcache/Python/3.8.18/x64/lib/python3.8/site-packages/nbclient/client.py", line 705, in async_execute
    await self.async_execute_cell(
  File "/opt/hostedtoolcache/Python/3.8.18/x64/lib/python3.8/site-packages/nbclient/client.py", line 1058, in async_execute_cell
    await self._check_raise_for_error(cell, cell_index, exec_reply)
  File "/opt/hostedtoolcache/Python/3.8.18/x64/lib/python3.8/site-packages/nbclient/client.py", line 914, in _check_raise_for_error
    raise CellExecutionError.from_cell_and_msg(cell, exec_reply_content)
nbclient.exceptions.CellExecutionError: An error occurred while executing the following cell:
------------------
def f(t, y):
    ''' Define a simple harmonic potential'''
    
    return np.array([y[1], -y[0]])


y  = np.array([1., 1.])
pos, vel = [], []
t  = 0
h = 0.1 

for i in range(1000):
    
    y = euler(y, f, t, h) # Change integration method venv, euler, rk2, rk4
    
    t+=h
    
    pos.append(y[0])
    vel.append(y[1])

fig, ax = plt.subplots(ncols=3, nrows=1, figsize=(12,3))

pos, vel =np.array(pos), np.array(vel)
ax[0].plot(pos, vel)
ax[1].plot(pos)
ax[1].plot(vel)
ax[2].plot(0.5*pos**2 + 0.5*vel**2)
------------------


[0;31m---------------------------------------------------------------------------[0m
[0;31mNameError[0m                                 Traceback (most recent call last)
Cell [0;32mIn[2], line 21[0m
[1;32m     18[0m     pos[38;5;241m.[39mappend(y[[38;5;241m0[39m])
[1;32m     19[0m     vel[38;5;241m.[39mappend(y[[38;5;241m1[39m])
[0;32m---> 21[0m fig, ax [38;5;241m=[39m [43mplt[49m[38;5;241m.[39msubplots(ncols[38;5;241m=[39m[38;5;241m3[39m, nrows[38;5;241m=[39m[38;5;241m1[39m, figsize[38;5;241m=[39m([38;5;241m12[39m,[38;5;241m3[39m))
[1;32m     23[0m pos, vel [38;5;241m=[39mnp[38;5;241m.[39marray(pos), np[38;5;241m.[39marray(vel)
[1;32m     24[0m ax[[38;5;241m0[39m][38;5;241m.[39mplot(pos, vel)

[0;31mNameError[0m: name 'plt' is not defined

