Traceback (most recent call last):
  File "/opt/hostedtoolcache/Python/3.8.18/x64/lib/python3.8/site-packages/jupyter_cache/executors/utils.py", line 58, in single_nb_execution
    executenb(
  File "/opt/hostedtoolcache/Python/3.8.18/x64/lib/python3.8/site-packages/nbclient/client.py", line 1305, in execute
    return NotebookClient(nb=nb, resources=resources, km=km, **kwargs).execute()
  File "/opt/hostedtoolcache/Python/3.8.18/x64/lib/python3.8/site-packages/jupyter_core/utils/__init__.py", line 165, in wrapped
    return loop.run_until_complete(inner)
  File "/opt/hostedtoolcache/Python/3.8.18/x64/lib/python3.8/asyncio/base_events.py", line 616, in run_until_complete
    return future.result()
  File "/opt/hostedtoolcache/Python/3.8.18/x64/lib/python3.8/site-packages/nbclient/client.py", line 705, in async_execute
    await self.async_execute_cell(
  File "/opt/hostedtoolcache/Python/3.8.18/x64/lib/python3.8/site-packages/nbclient/client.py", line 1058, in async_execute_cell
    await self._check_raise_for_error(cell, cell_index, exec_reply)
  File "/opt/hostedtoolcache/Python/3.8.18/x64/lib/python3.8/site-packages/nbclient/client.py", line 914, in _check_raise_for_error
    raise CellExecutionError.from_cell_and_msg(cell, exec_reply_content)
nbclient.exceptions.CellExecutionError: An error occurred while executing the following cell:
------------------
#%time 
confs, es = run_MC_LJ(pos, **params)
------------------


[0;31m---------------------------------------------------------------------------[0m
[0;31mNotDefinedError[0m                           Traceback (most recent call last)
Cell [0;32mIn[9], line 2[0m
[1;32m      1[0m [38;5;66;03m#%time [39;00m
[0;32m----> 2[0m confs, es [38;5;241m=[39m [43mrun_MC_LJ[49m[43m([49m[43mpos[49m[43m,[49m[43m [49m[38;5;241;43m*[39;49m[38;5;241;43m*[39;49m[43mparams[49m[43m)[49m

File [0;32m/opt/hostedtoolcache/Python/3.8.18/x64/lib/python3.8/site-packages/numba/core/dispatcher.py:476[0m, in [0;36m_DispatcherBase._compile_for_args[0;34m(self, *args, **kws)[0m
[1;32m    471[0m     error_rewrite(e, [38;5;124m'[39m[38;5;124munsupported_error[39m[38;5;124m'[39m)
[1;32m    472[0m [38;5;28;01mexcept[39;00m (errors[38;5;241m.[39mNotDefinedError, errors[38;5;241m.[39mRedefinedError,
[1;32m    473[0m         errors[38;5;241m.[39mVerificationError) [38;5;28;01mas[39;00m e:
[1;32m    474[0m     [38;5;66;03m# These errors are probably from an issue with either the code[39;00m
[1;32m    475[0m     [38;5;66;03m# supplied being syntactically or otherwise invalid[39;00m
[0;32m--> 476[0m     [43merror_rewrite[49m[43m([49m[43me[49m[43m,[49m[43m [49m[38;5;124;43m'[39;49m[38;5;124;43minterpreter[39;49m[38;5;124;43m'[39;49m[43m)[49m
[1;32m    477[0m [38;5;28;01mexcept[39;00m errors[38;5;241m.[39mConstantInferenceError [38;5;28;01mas[39;00m e:
[1;32m    478[0m     [38;5;66;03m# this is from trying to infer something as constant when it isn't[39;00m
[1;32m    479[0m     [38;5;66;03m# or isn't supported as a constant[39;00m
[1;32m    480[0m     error_rewrite(e, [38;5;124m'[39m[38;5;124mconstant_inference[39m[38;5;124m'[39m)

File [0;32m/opt/hostedtoolcache/Python/3.8.18/x64/lib/python3.8/site-packages/numba/core/dispatcher.py:409[0m, in [0;36m_DispatcherBase._compile_for_args.<locals>.error_rewrite[0;34m(e, issue_type)[0m
[1;32m    407[0m     [38;5;28;01mraise[39;00m e
[1;32m    408[0m [38;5;28;01melse[39;00m:
[0;32m--> 409[0m     [38;5;28;01mraise[39;00m e[38;5;241m.[39mwith_traceback([38;5;28;01mNone[39;00m)

[0;31mNotDefinedError[0m: Failed in nopython mode pipeline (step: analyzing bytecode)
The compiler failed to analyze the bytecode. Variable 'E_tot' is not defined.

File "../../../../../../tmp/ipykernel_2432/2393613982.py", line 39:
<source missing, REPL/exec in use?>


