Traceback (most recent call last):
  File "/opt/hostedtoolcache/Python/3.8.18/x64/lib/python3.8/site-packages/jupyter_cache/executors/utils.py", line 58, in single_nb_execution
    executenb(
  File "/opt/hostedtoolcache/Python/3.8.18/x64/lib/python3.8/site-packages/nbclient/client.py", line 1305, in execute
    return NotebookClient(nb=nb, resources=resources, km=km, **kwargs).execute()
  File "/opt/hostedtoolcache/Python/3.8.18/x64/lib/python3.8/site-packages/jupyter_core/utils/__init__.py", line 165, in wrapped
    return loop.run_until_complete(inner)
  File "/opt/hostedtoolcache/Python/3.8.18/x64/lib/python3.8/asyncio/base_events.py", line 616, in run_until_complete
    return future.result()
  File "/opt/hostedtoolcache/Python/3.8.18/x64/lib/python3.8/site-packages/nbclient/client.py", line 705, in async_execute
    await self.async_execute_cell(
  File "/opt/hostedtoolcache/Python/3.8.18/x64/lib/python3.8/site-packages/nbclient/client.py", line 1058, in async_execute_cell
    await self._check_raise_for_error(cell, cell_index, exec_reply)
  File "/opt/hostedtoolcache/Python/3.8.18/x64/lib/python3.8/site-packages/nbclient/client.py", line 914, in _check_raise_for_error
    raise CellExecutionError.from_cell_and_msg(cell, exec_reply_content)
nbclient.exceptions.CellExecutionError: An error occurred while executing the following cell:
------------------
import numpy as np
import pandas as pd
import matplotlib.pyplot as plt
plt.style.use("petroff10")
------------------


[0;31m---------------------------------------------------------------------------[0m
[0;31mFileNotFoundError[0m                         Traceback (most recent call last)
File [0;32m/opt/hostedtoolcache/Python/3.8.18/x64/lib/python3.8/site-packages/matplotlib/style/core.py:166[0m, in [0;36muse[0;34m(style)[0m
[1;32m    165[0m [38;5;28;01mtry[39;00m:
[0;32m--> 166[0m     style [38;5;241m=[39m [43m_rc_params_in_file[49m[43m([49m[43mstyle[49m[43m)[49m
[1;32m    167[0m [38;5;28;01mexcept[39;00m [38;5;167;01mIOError[39;00m [38;5;28;01mas[39;00m err:

File [0;32m/opt/hostedtoolcache/Python/3.8.18/x64/lib/python3.8/site-packages/matplotlib/__init__.py:854[0m, in [0;36m_rc_params_in_file[0;34m(fname, transform, fail_on_error)[0m
[1;32m    853[0m rc_temp [38;5;241m=[39m {}
[0;32m--> 854[0m [38;5;28;01mwith[39;00m _open_file_or_url(fname) [38;5;28;01mas[39;00m fd:
[1;32m    855[0m     [38;5;28;01mtry[39;00m:

File [0;32m/opt/hostedtoolcache/Python/3.8.18/x64/lib/python3.8/contextlib.py:113[0m, in [0;36m_GeneratorContextManager.__enter__[0;34m(self)[0m
[1;32m    112[0m [38;5;28;01mtry[39;00m:
[0;32m--> 113[0m     [38;5;28;01mreturn[39;00m [38;5;28;43mnext[39;49m[43m([49m[38;5;28;43mself[39;49m[38;5;241;43m.[39;49m[43mgen[49m[43m)[49m
[1;32m    114[0m [38;5;28;01mexcept[39;00m [38;5;167;01mStopIteration[39;00m:

File [0;32m/opt/hostedtoolcache/Python/3.8.18/x64/lib/python3.8/site-packages/matplotlib/__init__.py:831[0m, in [0;36m_open_file_or_url[0;34m(fname)[0m
[1;32m    830[0m fname [38;5;241m=[39m os[38;5;241m.[39mpath[38;5;241m.[39mexpanduser(fname)
[0;32m--> 831[0m [38;5;28;01mwith[39;00m [38;5;28;43mopen[39;49m[43m([49m[43mfname[49m[43m,[49m[43m [49m[43mencoding[49m[38;5;241;43m=[39;49m[38;5;124;43m'[39;49m[38;5;124;43mutf-8[39;49m[38;5;124;43m'[39;49m[43m)[49m [38;5;28;01mas[39;00m f:
[1;32m    832[0m     [38;5;28;01myield[39;00m f

[0;31mFileNotFoundError[0m: [Errno 2] No such file or directory: 'petroff10'

The above exception was the direct cause of the following exception:

[0;31mOSError[0m                                   Traceback (most recent call last)
Cell [0;32mIn[1], line 4[0m
[1;32m      2[0m [38;5;28;01mimport[39;00m[38;5;250m [39m[38;5;21;01mpandas[39;00m[38;5;250m [39m[38;5;28;01mas[39;00m[38;5;250m [39m[38;5;21;01mpd[39;00m
[1;32m      3[0m [38;5;28;01mimport[39;00m[38;5;250m [39m[38;5;21;01mmatplotlib[39;00m[38;5;21;01m.[39;00m[38;5;21;01mpyplot[39;00m[38;5;250m [39m[38;5;28;01mas[39;00m[38;5;250m [39m[38;5;21;01mplt[39;00m
[0;32m----> 4[0m [43mplt[49m[38;5;241;43m.[39;49m[43mstyle[49m[38;5;241;43m.[39;49m[43muse[49m[43m([49m[38;5;124;43m"[39;49m[38;5;124;43mpetroff10[39;49m[38;5;124;43m"[39;49m[43m)[49m

File [0;32m/opt/hostedtoolcache/Python/3.8.18/x64/lib/python3.8/site-packages/matplotlib/style/core.py:168[0m, in [0;36muse[0;34m(style)[0m
[1;32m    166[0m         style [38;5;241m=[39m _rc_params_in_file(style)
[1;32m    167[0m     [38;5;28;01mexcept[39;00m [38;5;167;01mIOError[39;00m [38;5;28;01mas[39;00m err:
[0;32m--> 168[0m         [38;5;28;01mraise[39;00m [38;5;167;01mIOError[39;00m(
[1;32m    169[0m             [38;5;124mf[39m[38;5;124m"[39m[38;5;132;01m{[39;00mstyle[38;5;132;01m!r}[39;00m[38;5;124m is not a valid package style, path of style [39m[38;5;124m"[39m
[1;32m    170[0m             [38;5;124mf[39m[38;5;124m"[39m[38;5;124mfile, URL of style file, or library style name (library [39m[38;5;124m"[39m
[1;32m    171[0m             [38;5;124mf[39m[38;5;124m"[39m[38;5;124mstyles are listed in `style.available`)[39m[38;5;124m"[39m) [38;5;28;01mfrom[39;00m[38;5;250m [39m[38;5;21;01merr[39;00m
[1;32m    172[0m filtered [38;5;241m=[39m {}
[1;32m    173[0m [38;5;28;01mfor[39;00m k [38;5;129;01min[39;00m style:  [38;5;66;03m# don't trigger RcParams.__getitem__('backend')[39;00m

[0;31mOSError[0m: 'petroff10' is not a valid package style, path of style file, URL of style file, or library style name (library styles are listed in `style.available`)

